2025-07-29 12:24:23,469 - CRITICAL - database - Не удалось создать пул соединений с MySQL: (1045, "Access denied for user 'catdevpon_nh'@'ec2-3-8-181-249.eu-west-2.compute.amazonaws.com' (using password: YES)")
Traceback (most recent call last):
  File "/root/nh/database.py", line 17, in init_pool
    pool = await aiomysql.create_pool(
  File "/usr/local/lib/python3.10/dist-packages/aiomysql/pool.py", line 29, in _create_pool
    await pool._fill_free_pool(False)
  File "/usr/local/lib/python3.10/dist-packages/aiomysql/pool.py", line 182, in _fill_free_pool
    conn = await connect(echo=self._echo, loop=self._loop,
  File "/usr/local/lib/python3.10/dist-packages/aiomysql/connection.py", line 75, in _connect
    await conn._connect()
  File "/usr/local/lib/python3.10/dist-packages/aiomysql/connection.py", line 540, in _connect
    await self._request_authentication()
  File "/usr/local/lib/python3.10/dist-packages/aiomysql/connection.py", line 855, in _request_authentication
    await self._process_auth(plugin_name, auth_packet)
  File "/usr/local/lib/python3.10/dist-packages/aiomysql/connection.py", line 878, in _process_auth
    await self.sha256_password_auth(auth_packet)
  File "/usr/local/lib/python3.10/dist-packages/aiomysql/connection.py", line 1029, in sha256_password_auth
    pkt = await self._read_packet()
  File "/usr/local/lib/python3.10/dist-packages/aiomysql/connection.py", line 652, in _read_packet
    packet.raise_for_error()
  File "/usr/local/lib/python3.10/dist-packages/pymysql/protocol.py", line 219, in raise_for_error
    err.raise_mysql_exception(self._data)
  File "/usr/local/lib/python3.10/dist-packages/pymysql/err.py", line 150, in raise_mysql_exception
    raise errorclass(errno, errval)
pymysql.err.OperationalError: (1045, "Access denied for user 'catdevpon_nh'@'ec2-3-8-181-249.eu-west-2.compute.amazonaws.com' (using password: YES)")
2025-07-29 12:24:23,470 - CRITICAL - root - !!! A CRITICAL ERROR OCCURRED !!!
Traceback (most recent call last):
  File "/root/nh/bot.py", line 531, in main
    await db.init_pool()
  File "/root/nh/database.py", line 17, in init_pool
    pool = await aiomysql.create_pool(
  File "/usr/local/lib/python3.10/dist-packages/aiomysql/pool.py", line 29, in _create_pool
    await pool._fill_free_pool(False)
  File "/usr/local/lib/python3.10/dist-packages/aiomysql/pool.py", line 182, in _fill_free_pool
    conn = await connect(echo=self._echo, loop=self._loop,
  File "/usr/local/lib/python3.10/dist-packages/aiomysql/connection.py", line 75, in _connect
    await conn._connect()
  File "/usr/local/lib/python3.10/dist-packages/aiomysql/connection.py", line 540, in _connect
    await self._request_authentication()
  File "/usr/local/lib/python3.10/dist-packages/aiomysql/connection.py", line 855, in _request_authentication
    await self._process_auth(plugin_name, auth_packet)
  File "/usr/local/lib/python3.10/dist-packages/aiomysql/connection.py", line 878, in _process_auth
    await self.sha256_password_auth(auth_packet)
  File "/usr/local/lib/python3.10/dist-packages/aiomysql/connection.py", line 1029, in sha256_password_auth
    pkt = await self._read_packet()
  File "/usr/local/lib/python3.10/dist-packages/aiomysql/connection.py", line 652, in _read_packet
    packet.raise_for_error()
  File "/usr/local/lib/python3.10/dist-packages/pymysql/protocol.py", line 219, in raise_for_error
    err.raise_mysql_exception(self._data)
  File "/usr/local/lib/python3.10/dist-packages/pymysql/err.py", line 150, in raise_mysql_exception
    raise errorclass(errno, errval)
pymysql.err.OperationalError: (1045, "Access denied for user 'catdevpon_nh'@'ec2-3-8-181-249.eu-west-2.compute.amazonaws.com' (using password: YES)")
