2025-07-29 10:01:29,683 - ERROR - root - /usr/local/lib/python3.10/dist-packages/aiomysql/cursors.py:239: Warning: Table 'users' already exists
  await self._query(query)
2025-07-29 10:01:29,736 - ERROR - root - /usr/local/lib/python3.10/dist-packages/aiomysql/cursors.py:239: Warning: Table 'userbots' already exists
  await self._query(query)
2025-07-29 10:01:29,788 - ERROR - root - /usr/local/lib/python3.10/dist-packages/aiomysql/cursors.py:239: Warning: Table 'commits' already exists
  await self._query(query)
2025-07-29 10:01:29,814 - ERROR - root - /usr/local/lib/python3.10/dist-packages/aiomysql/cursors.py:239: Warning: Table 'commit_votes' already exists
  await self._query(query)
2025-07-29 10:01:29,840 - ERROR - root - /usr/local/lib/python3.10/dist-packages/aiomysql/cursors.py:239: Warning: Table 'userbot_shared' already exists
  await self._query(query)
2025-07-29 10:02:03,508 - WARNING - system_manager - ProcessError on [3.72.64.44]. Command: sudo. Error: usage: sudo -h | -K | -k | -V
usage: sudo -v [-ABknS] [-g group] [-h host] [-p prompt] [-u user]
usage: sudo -l [-ABknS] [-g group] [-h host] [-p prompt] [-U user] [-u user]
            [command]
usage: sudo [-ABbEHknPS] [-r role] [-t type] [-C num] [-D directory] [-g group]
            [-h host] [-p prompt] [-R directory] [-T timeout] [-u user]
            [VAR=value] [-i|-s] [<command>]
usage: sudo -e [-ABknS] [-r role] [-t type] [-C num] [-D directory] [-g group]
            [-h host] [-p prompt] [-R directory] [-T timeout] [-u user] file ...

2025-07-29 10:02:06,333 - WARNING - system_manager - ProcessError on [3.72.64.44]. Command: sudo. Error: usage: sudo -h | -K | -k | -V
usage: sudo -v [-ABknS] [-g group] [-h host] [-p prompt] [-u user]
usage: sudo -l [-ABknS] [-g group] [-h host] [-p prompt] [-U user] [-u user]
            [command]
usage: sudo [-ABbEHknPS] [-r role] [-t type] [-C num] [-D directory] [-g group]
            [-h host] [-p prompt] [-R directory] [-T timeout] [-u user]
            [VAR=value] [-i|-s] [<command>]
usage: sudo -e [-ABknS] [-r role] [-t type] [-C num] [-D directory] [-g group]
            [-h host] [-p prompt] [-R directory] [-T timeout] [-u user] file ...

2025-07-29 10:02:07,135 - WARNING - system_manager - ProcessError on [3.72.64.44]. Command: 'sudo adduser'. Error: sudo: a terminal is required to read the password; either use the -S option to read from standard input or configure an askpass helper
sudo: a password is required

2025-07-29 10:02:10,304 - WARNING - system_manager - ProcessError on [3.72.64.44]. Command: 'sudo ls'. Error: sudo: a terminal is required to read the password; either use the -S option to read from standard input or configure an askpass helper
sudo: a password is required

2025-07-29 10:02:26,647 - WARNING - system_manager - ProcessError on [3.72.64.44]. Command: 'ls /root'. Error: ls: cannot open directory '/root': Permission denied

2025-07-29 10:07:18,293 - ERROR - system_manager - EXCEPTION on [84.201.142.34]. Command: 'sudo systemctl is-active hikka-ub1288092948.service'
Traceback (most recent call last):
  File "/root/nh/system_manager.py", line 531, in run_command_async
    async with asyncssh.connect(server_ip, username=ssh_user, password=ssh_pass_final, known_hosts=None, connect_timeout=10) as conn:
  File "/usr/local/lib/python3.10/dist-packages/asyncssh/misc.py", line 386, in __aenter__
    self._coro_result = await self._coro
  File "/usr/local/lib/python3.10/dist-packages/asyncssh/connection.py", line 9186, in connect
    return await asyncio.wait_for(
  File "/usr/lib/python3.10/asyncio/tasks.py", line 445, in wait_for
    return fut.result()
  File "/usr/local/lib/python3.10/dist-packages/asyncssh/connection.py", line 528, in _connect
    await options.waiter
asyncssh.misc.ConnectionLost: Connection lost
2025-07-29 10:07:20,763 - ERROR - system_manager - EXCEPTION on [84.201.142.34]. Command: 'sudo journalctl -u hikka-ub1288092948.service --no-pager -n 500 --output cat -r'
Traceback (most recent call last):
  File "/root/nh/system_manager.py", line 531, in run_command_async
    async with asyncssh.connect(server_ip, username=ssh_user, password=ssh_pass_final, known_hosts=None, connect_timeout=10) as conn:
  File "/usr/local/lib/python3.10/dist-packages/asyncssh/misc.py", line 386, in __aenter__
    self._coro_result = await self._coro
  File "/usr/local/lib/python3.10/dist-packages/asyncssh/connection.py", line 9186, in connect
    return await asyncio.wait_for(
  File "/usr/lib/python3.10/asyncio/tasks.py", line 445, in wait_for
    return fut.result()
  File "/usr/local/lib/python3.10/dist-packages/asyncssh/connection.py", line 528, in _connect
    await options.waiter
asyncssh.misc.ConnectionLost: Connection lost
2025-07-29 10:07:38,065 - ERROR - system_manager - EXCEPTION on [84.201.142.34]. Command: 'top -bn1 | awk '"'"'/^%Cpu/ {print $2+$4}'"'"' && echo '"'"'---'"'"' && free -m | awk '"'"'NR==2{printf "%d|%d", $3, $2}'"'"' && echo '"'"'---'"'"' && df -h / | awk '"'"'NR==2{printf "%s|%s|%s", $5, $3, $2}'"'"' && echo '"'"'---'"'"' && uptime -p && echo '"'"'---'"'"' && nproc'
Traceback (most recent call last):
  File "/root/nh/system_manager.py", line 531, in run_command_async
    async with asyncssh.connect(server_ip, username=ssh_user, password=ssh_pass_final, known_hosts=None, connect_timeout=10) as conn:
  File "/usr/local/lib/python3.10/dist-packages/asyncssh/misc.py", line 386, in __aenter__
    self._coro_result = await self._coro
  File "/usr/local/lib/python3.10/dist-packages/asyncssh/connection.py", line 9186, in connect
    return await asyncio.wait_for(
  File "/usr/lib/python3.10/asyncio/tasks.py", line 445, in wait_for
    return fut.result()
  File "/usr/local/lib/python3.10/dist-packages/asyncssh/connection.py", line 528, in _connect
    await options.waiter
asyncssh.misc.ConnectionLost: Connection lost
